<robot name="rover_robot">

<link name="dummy_link">
          
</link>
<link name="base_link">
          <inertial>
                    <origin xyz="0.0 0.0 0.0" rpy="0.0 0.0 0.0"/>
                    <mass value="0.0"/>
                    <inertia ixx="0.0" ixy="0.0" ixz="0.0" iyy="0.0" iyz="0.0" izz="0.0"/>
          </inertial>
          <visual name="">
                    <origin xyz="0.0 0.0 0.0" rpy="0.0 0.0 0.0"/>
                    <geometry>
                              <box size="0.75 0.4 0.1"/>
                    </geometry>
                    <material name="">
                              <color rgba="1.0 0.0 0.0 1.0"/>
                              <texture filename=""/>
                    </material>
          </visual>
          <collision>
                    <origin xyz="0.0 0.0 0.0" rpy="0.0 0.0 0.0"/>
                    <geometry>
                              <box size="0.0 0.0 0.0"/>
                    </geometry>
          </collision>
</link>

<joint name="base_joint" type="fixed">
          <origin xyz="0.0 0.0 0.135" rpy="0.0 0.0 0.0"/>
          <parent link="dummy_link"/>
          <child link="base_link"/>
          <axis xyz="0.0 0.0 0.0"/>
          
</joint>

<!-- Rear Right Wheel-->

<link name="rear_right_wheel_link">
          <inertial>
                    <origin xyz="0.0 0.0 0.0" rpy="0.0 0.0 0.0"/>
                    <mass value="0.0"/>
                    <inertia ixx="0.0" ixy="0.0" ixz="0.0" iyy="0.0" iyz="0.0" izz="0.0"/>
          </inertial>
          <visual name="">
                    <origin xyz="0.0 0.0 0.0" rpy="0.0 0.0 0.0"/>
                    <geometry>
                              <cylinder radius="0.15" length="0.1"/>
                    </geometry>
                    <material name="">
                              <color rgba="1.0 1.0 1.0 1.0"/>
                              <texture filename=""/>
                    </material>
          </visual>
          <collision>
                    <origin xyz="0.0 0.0 0.0" rpy="0.0 0.0 0.0"/>
                    <geometry>
                              <box size="0.0 0.0 0.0"/>
                    </geometry>
          </collision>
</link>
<joint name="rear_right_wheel_joint" type="continuous">
          <origin xyz="-0.25 0.25 0.0" rpy="1.57 0.0 0.0"/>
          <parent link="base_link"/>
          <child link="rear_right_wheel_link"/>
          <axis xyz="0.0 0.0 1.0"/>
          
</joint>


<!-- Rear left Wheel-->

<link name="rear_left_wheel_link">
          <inertial>
                    <origin xyz="0.0 0.0 0.0" rpy="0.0 0.0 0.0"/>
                    <mass value="0.0"/>
                    <inertia ixx="0.0" ixy="0.0" ixz="0.0" iyy="0.0" iyz="0.0" izz="0.0"/>
          </inertial>
          <visual name="">
                    <origin xyz="0.0 0.0 0.0" rpy="0.0 0.0 0.0"/>
                    <geometry>
                              <cylinder radius="0.15" length="0.1"/>
                    </geometry>
                    <material name="">
                              <color rgba="1.0 1.0 1.0 1.0"/>
                              <texture filename=""/>
                    </material>
          </visual>
          <collision>
                    <origin xyz="0.0 0.0 0.0" rpy="0.0 0.0 0.0"/>
                    <geometry>
                              <box size="0.0 0.0 0.0"/>
                    </geometry>
          </collision>
</link>

<joint name="rear_left_wheel_joint" type="continuous">
          <origin xyz="-0.25 -0.25 0.0" rpy="1.57 0.0 0.0"/>
          <parent link="base_link"/>
          <child link="rear_left_wheel_link"/>
          <axis xyz="0.0 0.0 1.0"/>
          
</joint>


<!-- Front Right Wheel-->

<link name="front_right_wheel_link">
          <inertial>
                    <origin xyz="0.0 0.0 0.0" rpy="0.0 0.0 0.0"/>
                    <mass value="0.0"/>
                    <inertia ixx="0.0" ixy="0.0" ixz="0.0" iyy="0.0" iyz="0.0" izz="0.0"/>
          </inertial>
          <visual name="">
                    <origin xyz="0.0 0.0 0.0" rpy="0.0 0.0 0.0"/>
                    <geometry>
                              <cylinder radius="0.15" length="0.1"/>
                    </geometry>
                    <material name="">
                              <color rgba="1.0 1.0 1.0 1.0"/>
                              <texture filename=""/>
                    </material>
          </visual>
          <collision>
                    <origin xyz="0.0 0.0 0.0" rpy="0.0 0.0 0.0"/>
                    <geometry>
                              <box size="0.0 0.0 0.0"/>
                    </geometry>
          </collision>
</link>
<joint name="front_right_wheel_joint" type="continuous">
          <origin xyz="0.25 0.25 0.0" rpy="1.57 0.0 0.0"/>
          <parent link="base_link"/>
          <child link="front_right_wheel_link"/>
          <axis xyz="0.0 0.0 1.0"/>
          
</joint>


<!-- Front left Wheel-->

<link name="front_left_wheel_link">
          <inertial>
                    <origin xyz="0.0 0.0 0.0" rpy="0.0 0.0 0.0"/>
                    <mass value="0.0"/>
                    <inertia ixx="0.0" ixy="0.0" ixz="0.0" iyy="0.0" iyz="0.0" izz="0.0"/>
          </inertial>
          <visual name="">
                    <origin xyz="0.0 0.0 0.0" rpy="0.0 0.0 0.0"/>
                    <geometry>
                              <cylinder radius="0.15" length="0.1"/>
                    </geometry>
                    <material name="">
                              <color rgba="1.0 1.0 1.0 1.0"/>
                              <texture filename=""/>
                    </material>
          </visual>
          <collision>
                    <origin xyz="0.0 0.0 0.0" rpy="0.0 0.0 0.0"/>
                    <geometry>
                              <box size="0.0 0.0 0.0"/>
                    </geometry>
          </collision>
</link>

<joint name="front_left_wheel_joint" type="continuous">
          <origin xyz="0.25 -0.25 0.0" rpy="1.57 0.0 0.0"/>
          <parent link="base_link"/>
          <child link="front_left_wheel_link"/>
          <axis xyz="0.0 0.0 1.0"/>
          
</joint>

</robot>